Workbook

Sheet Forecast - summary
A1: BEV and PHEV Forecasts
A3: Car Parc forecast | J3: Manheim Market Share forecast | P3: Comparing naive and strategic forecasts
A35: EV forecast yearly summary
B37: BEV forecast | H37: PHEV forecast | N37: EV forecast (BEV + PHEV) | Q37: Strategic forecast
B38: UK EV Car Parc | E38: Manheim Market Share | H38: UK EV Car Parc | K38: Manheim Market Share | N38: UK EV Car Parc | Q38: UK EV Car Parc | T38: manheim mid | U38: manheim high
A39: Year | B39: BEV | C39: BEV_low | D39: BEV_high | E39: BEV | F39: BEV_low | G39: BEV_high | H39: PHEV | I39: PHEV_low | J39: PHEV_high | K39: PHEV | L39: PHEV_low | M39: PHEV_high | N39: EV | O39: EV_low | P39: EV_high | Q39: EV
A40: 2022 | B40: ='EV forecast data'!C11 -> 662645.96 | C40: ='EV forecast data'!D11 -> 627004.57 | D40: ='EV forecast data'!E11 -> 698287.35 | E40: ='EV forecast data'!F11 -> 4331.054 | F40: ='EV forecast data'!G11 -> 4098.1018 | G40: ='EV forecast data'!H11 -> 4564.0061 | H40: ='EV forecast data'!I11 -> 429861 | I40: ='EV forecast data'!J11 -> 401114.33 | ... M40: ='EV forecast data'!N11 -> 2997.4598 | N40: =B40+H40 -> 1092507 | O40: =C40+I40 -> 1028118.9 | P40: =D40+J40 -> 1156895 | Q40: ='Umar''s EV forecast'!Q20 -> 1156844.5 | S40: =E40+K40 -> 7140.6255 | T40: =E40+K40 -> 7140.6255 | U40: =G40+M40 -> 7561.4659
A41: 2023 | B41: ='EV forecast data'!C15 -> 1004266.4 | C41: ='EV forecast data'!D15 -> 879625.78 | D41: ='EV forecast data'!E15 -> 1128906.9 | E41: ='EV forecast data'!F15 -> 6563.8849 | F41: ='EV forecast data'!G15 -> 5749.2341 | G41: ='EV forecast data'!H15 -> 7378.5358 | H41: ='EV forecast data'!I15 -> 538281 | I41: ='EV forecast data'!J15 -> 447376.04 | ... M41: ='EV forecast data'!N15 -> 4112.3595 | N41: =B41+H41 -> 1542547.4 | O41: =C41+I41 -> 1327001.8 | P41: =D41+J41 -> 1758092.9 | Q41: ='Umar''s EV forecast'!R20 -> 1741038.3 | S41: =E41+K41 -> 10082.09 | T41: =E41+K41 -> 10082.09 | U41: =G41+M41 -> 11490.895
A42: 2024 | B42: ='EV forecast data'!C19 -> 1380755.8 | C42: ='EV forecast data'!D19 -> 1112403.6 | D42: ='EV forecast data'!E19 -> 1649108.1 | E42: ='EV forecast data'!F19 -> 9024.6201 | F42: ='EV forecast data'!G19 -> 7270.6697 | G42: ='EV forecast data'!H19 -> 10778.571 | H42: ='EV forecast data'!I19 -> 646701 | I42: ='EV forecast data'!J19 -> 473879.07 | ... M42: ='EV forecast data'!N19 -> 5356.4018 | N42: =B42+H42 -> 2027456.8 | O42: =C42+I42 -> 1586282.6 | P42: =D42+J42 -> 2468631 | Q42: ='Umar''s EV forecast'!S20 -> 2369397.8 | S42: =E42+K42 -> 13251.458 | T42: =E42+K42 -> 13251.458 | U42: =G42+M42 -> 16134.972
A43: 2025 | B43: ='EV forecast data'!C23 -> 1778145.7 | C43: ='EV forecast data'!D23 -> 1316011.1 | D43: ='EV forecast data'!E23 -> 2240280.3 | E43: ='EV forecast data'!F23 -> 11621.96 | F43: ='EV forecast data'!G23 -> 8601.4486 | G43: ='EV forecast data'!H23 -> 14642.472 | H43: ='EV forecast data'!I23 -> 755121 | I43: ='EV forecast data'!J23 -> 484579.17 | ... M43: ='EV forecast data'!N23 -> 6703.7323 | N43: =B43+H43 -> 2533266.7 | O43: =C43+I43 -> 1800590.3 | P43: =D43+J43 -> 3265943.1 | Q43: ='Umar''s EV forecast'!T20 -> 3130907.5 | S43: =E43+K43 -> 16557.431 | T43: =E43+K43 -> 16557.431 | U43: =G43+M43 -> 21346.204
A44: 2026 | B44: ='EV forecast data'!C27 -> 2188063.4 | C44: ='EV forecast data'!D27 -> 1487132.9 | D44: ='EV forecast data'!E27 -> 2888993.8 | E44: ='EV forecast data'!F27 -> 14301.182 | F44: ='EV forecast data'!G27 -> 9719.9007 | G44: ='EV forecast data'!H27 -> 18882.464 | H44: ='EV forecast data'!I27 -> 863541 | I44: ='EV forecast data'!J27 -> 481709.23 | ... M44: ='EV forecast data'!N27 -> 8139.7564 | N44: =B44+H44 -> 3051604.4 | O44: =C44+I44 -> 1968842.1 | P44: =D44+J44 -> 4134366.6 | Q44: ='Umar''s EV forecast'!U20 -> 3997348.2 | S44: =E44+K44 -> 19945.286 | T44: =E44+K44 -> 19945.286 | U44: =G44+M44 -> 27022.22
A45: 2027 | B45: ='EV forecast data'!C31 -> 2605490.3 | C45: ='EV forecast data'!D31 -> 1625373.2 | D45: ='EV forecast data'!E31 -> 3585607.4 | E45: ='EV forecast data'!F31 -> 17029.484 | F45: ='EV forecast data'!G31 -> 10623.439 | G45: ='EV forecast data'!H31 -> 23435.53 | H45: ='EV forecast data'!I31 -> 971961 | I45: ='EV forecast data'!J31 -> 466757.41 | ... M45: ='EV forecast data'!N31 -> 9654.7477 | N45: =B45+H45 -> 3577451.3 | O45: =C45+I45 -> 2092130.6 | P45: =D45+J45 -> 5062772 | Q45: ='Umar''s EV forecast'!V20 -> 5021482.3 | S45: =E45+K45 -> 23382.221 | T45: =E45+K45 -> 23382.221 | U45: =G45+M45 -> 33090.278
A46: 2028 | B46: ='EV forecast data'!C35 -> 3027418.2 | C46: ='EV forecast data'!D35 -> 1731684.3 | D46: ='EV forecast data'!E35 -> 4323152.2 | E46: ='EV forecast data'!F35 -> 19787.206 | F46: ='EV forecast data'!G35 -> 11318.289 | G46: ='EV forecast data'!H35 -> 28256.123 | H46: ='EV forecast data'!I35 -> 1080381 | I46: ='EV forecast data'!J35 -> 440807.88 | ... M46: ='EV forecast data'!N35 -> 11241.62 | N46: =B46+H46 -> 4107799.2 | O46: =C46+I46 -> 2172492.2 | P46: =D46+J46 -> 6043106.3 | Q46: ='Umar''s EV forecast'!W20 -> 6200101.1 | S46: =E46+K46 -> 26848.576 | T46: =E46+K46 -> 26848.576 | U46: =G46+M46 -> 39497.743
A47: 2029 | B47: ='EV forecast data'!C39 -> 3452044.1 | C47: ='EV forecast data'!D39 -> 1807568.4 | D47: ='EV forecast data'!E39 -> 5096519.9 | E47: ='EV forecast data'!F39 -> 22562.561 | F47: ='EV forecast data'!G39 -> 11814.267 | G47: ='EV forecast data'!H39 -> 33310.854 | H47: ='EV forecast data'!I39 -> 1188801 | I47: ='EV forecast data'!J39 -> 404696.28 | ... M47: ='EV forecast data'!N39 -> 12894.912 | N47: =B47+H47 -> 4640845.1 | O47: =C47+I47 -> 2212264.7 | P47: =D47+J47 -> 7069425.6 | Q47: ='Umar''s EV forecast'!X20 -> 7603009.4 | S47: =E47+K47 -> 30332.564 | T47: =E47+K47 -> 30332.564 | U47: =G47+M47 -> 46205.766
A48: 2030 | B48: ='EV forecast data'!C43 -> 3878287.2 | C48: ='EV forecast data'!D43 -> 1854679 | D48: ='EV forecast data'!E43 -> 5901895.5 | E48: ='EV forecast data'!F43 -> 25348.485 | F48: ='EV forecast data'!G43 -> 12122.182 | G48: ='EV forecast data'!H43 -> 38574.789 | H48: ='EV forecast data'!I43 -> 1297221 | I48: ='EV forecast data'!J43 -> 359092.34 | ... M48: ='EV forecast data'!N43 -> 14610.245 | N48: =B48+H48 -> 5175508.2 | O48: =C48+I48 -> 2213771.3 | P48: =D48+J48 -> 8137245.2 | Q48: ='Umar''s EV forecast'!Y20 -> 9202227 | S48: =E48+K48 -> 33827.122 | T48: =E48+K48 -> 33827.122 | U48: =G48+M48 -> 53185.035
A49: 2031 | B49: ='EV forecast data'!C47 -> 4305499.7 | C49: ='EV forecast data'!D47 -> 1874631 | D49: ='EV forecast data'!E47 -> 6736368.4 | E49: ='EV forecast data'!F47 -> 28140.746 | F49: ='EV forecast data'!G47 -> 12252.588 | G49: ='EV forecast data'!H47 -> 44028.904 | H49: ='EV forecast data'!I47 -> 1405641 | I49: ='EV forecast data'!J47 -> 304548.5 | ... M49: ='EV forecast data'!N47 -> 16384.01 | N49: =B49+H49 -> 5711140.7 | O49: =C49+I49 -> 2179179.5 | P49: =D49+J49 -> 9243101.9 | Q49: ='Umar''s EV forecast'!Z20 -> 10867832 | S49: =E49+K49 -> 37328.015 | T49: =E49+K49 -> 37328.015 | U49: =G49+M49 -> 60412.914
A50: 2032 | B50: ='EV forecast data'!C51 -> 4733293.1 | C50: ='EV forecast data'!D51 -> 1868919.6 | D50: ='EV forecast data'!E51 -> 7597666.7 | E50: ='EV forecast data'!F51 -> 30936.804 | F50: ='EV forecast data'!G51 -> 12215.258 | G50: ='EV forecast data'!H51 -> 49658.35 | H50: ='EV forecast data'!I51 -> 1514061 | I50: ='EV forecast data'!J51 -> 241530.64 | ... M50: ='EV forecast data'!N51 -> 18213.161 | N50: =B50+H50 -> 6247354.1 | O50: =C50+I50 -> 2110450.2 | P50: =D50+J50 -> 10384258 | Q50: ='Umar''s EV forecast'!AA20 -> 12475911 | S50: =E50+K50 -> 40832.707 | T50: =E50+K50 -> 40832.707 | U50: =G50+M50 -> 67871.511
R69: S

Sheet EV forecast data
A1: Wholesale market | C1: 3.8 | D1: percent of car parc
A2: Manheim market share | C2: 17.2 | D2: percent of wholesale
A3: Manheim market share | C3: =C1*C2/100 -> 0.6536 | D3: percent of car parc
H5: Quarterly forecast based on ONS data
C6: BEV forecast | I6: PHEV forecast
C7: UK EV Car Parc | F7: Manheim Market Share | I7: UK EV Car Parc | L7: Manheim Market Share
A8: Date | B8: Quarter | C8: BEV | D8: BEV_low | E8: BEV_high | F8: BEV | G8: BEV_low | H8: BEV_high | I8: PHEV | J8: PHEV_low | K8: PHEV_high | L8: PHEV | M8: PHEV_low | N8: PHEV_high
A9: 44652 | B9: 2022 Q2 | C9: 508620.6 | D9: 496950.29 | E9: 520290.92 | F9: =C9*$C$3/100 -> 3324.3443 | G9: =D9*$C$3/100 -> 3248.0671 | H9: =E9*$C$3/100 -> 3400.6214 | I9: 375651 | J9: 367968.13 | K9: 383333.87 | L9: =I9*$C$3/100 -> 2455.2549 | M9: =J9*$C$3/100 -> 2405.0397 | N9: =K9*$C$3/100 -> 2505.4702
A10: 44743 | B10: 2022 Q3 | C10: 581288.08 | D10: 559051.57 | E10: 603524.58 | F10: =C10*$C$3/100 -> 3799.2989 | G10: =D10*$C$3/100 -> 3653.9611 | H10: =E10*$C$3/100 -> 3944.6367 | I10: 402756 | J10: 385576.58 | K10: 419935.42 | L10: =I10*$C$3/100 -> 2632.4132 | M10: =J10*$C$3/100 -> 2520.1285 | N10: =K10*$C$3/100 -> 2744.6979
A11: 44835 | B11: 2022 Q4 | C11: 662645.96 | D11: 627004.57 | E11: 698287.35 | F11: =C11*$C$3/100 -> 4331.054 | G11: =D11*$C$3/100 -> 4098.1018 | H11: =E11*$C$3/100 -> 4564.0061 | I11: 429861 | J11: 401114.33 | K11: 458607.67 | L11: =I11*$C$3/100 -> 2809.5715 | M11: =J11*$C$3/100 -> 2621.6832 | N11: =K11*$C$3/100 -> 2997.4598
A12: 44927 | B12: 2023 Q1 | C12: 742726.25 | D12: 691961.34 | E12: 793491.17 | F12: =C12*$C$3/100 -> 4854.4588 | G12: =D12*$C$3/100 -> 4522.6593 | H12: =E12*$C$3/100 -> 5186.2583 | I12: 456966 | J12: 414885.18 | K12: 499046.82 | L12: =I12*$C$3/100 -> 2986.7298 | M12: =J12*$C$3/100 -> 2711.6895 | N12: =K12*$C$3/100 -> 3261.77
A13: 45017 | B13: 2023 Q2 | C13: 826080.96 | D13: 753639.81 | E13: 898522.11 | F13: =C13*$C$3/100 -> 5399.2652 | G13: =D13*$C$3/100 -> 4925.7898 | H13: =E13*$C$3/100 -> 5872.7405 | I13: 484071 | J13: 427093.3 | K13: 541048.7 | L13: =I13*$C$3/100 -> 3163.8881 | M13: =J13*$C$3/100 -> 2791.4818 | N13: =K13*$C$3/100 -> 3536.2943
A14: 45108 | B14: 2023 Q3 | C14: 912571.05 | D14: 815594.93 | E14: 1009547.2 | F14: =C14*$C$3/100 -> 5964.5644 | G14: =D14*$C$3/100 -> 5330.7284 | H14: =E14*$C$3/100 -> 6598.4003 | I14: 511176 | J14: 437886.07 | K14: 584465.93 | L14: =I14*$C$3/100 -> 3341.0463 | M14: =J14*$C$3/100 -> 2862.0234 | N14: =K14*$C$3/100 -> 3820.0693
A15: 45200 | B15: 2023 Q4 | C15: 1004266.4 | D15: 879625.78 | E15: 1128906.9 | F15: =C15*$C$3/100 -> 6563.8849 | G15: =D15*$C$3/100 -> 5749.2341 | H15: =E15*$C$3/100 -> 7378.5358 | I15: 538281 | J15: 447376.04 | K15: 629185.96 | L15: =I15*$C$3/100 -> 3518.2046 | M15: =J15*$C$3/100 -> 2924.0498 | N15: =K15*$C$3/100 -> 4112.3595
A16: 45292 | B16: 2024 Q1 | C16: 1095197.3 | D16: 940436.34 | E16: 1249958.3 | F16: =C16*$C$3/100 -> 7158.2098 | G16: =D16*$C$3/100 -> 6146.6919 | H16: =E16*$C$3/100 -> 8169.7277 | I16: 565386 | J16: 455652.64 | K16: 675119.36 | L16: =I16*$C$3/100 -> 3695.3629 | M16: =J16*$C$3/100 -> 2978.1457 | N16: =K16*$C$3/100 -> 4412.5801
A17: 45383 | B17: 2024 Q2 | C17: 1188090.5 | D17: 998500.16 | E17: 1377680.8 | F17: =C17*$C$3/100 -> 7765.3593 | G17: =D17*$C$3/100 -> 6526.1971 | H17: =E17*$C$3/100 -> 9004.5215 | I17: 592491 | J17: 462789.2 | K17: 722192.8 | L17: =I17*$C$3/100 -> 3872.5212 | M17: =J17*$C$3/100 -> 3024.7902 | N17: =K17*$C$3/100 -> 4720.2522
A18: 45474 | B18: 2024 Q3 | C18: 1282863.2 | D18: 1055414.8 | E18: 1510311.5 | F18: =C18*$C$3/100 -> 8384.7937 | G18: =D18*$C$3/100 -> 6898.1912 | H18: =E18*$C$3/100 -> 9871.3962 | I18: 619596 | J18: 468847.17 | K18: 770344.83 | L18: =I18*$C$3/100 -> 4049.6795 | M18: =J18*$C$3/100 -> 3064.3851 | N18: =K18*$C$3/100 -> 5034.9738
A19: 45566 | B19: 2024 Q4 | C19: 1380755.8 | D19: 1112403.6 | E19: 1649108.1 | F19: =C19*$C$3/100 -> 9024.6201 | G19: =D19*$C$3/100 -> 7270.6697 | H19: =E19*$C$3/100 -> 10778.571 | I19: 646701 | J19: 473879.07 | K19: 819522.93 | L19: =I19*$C$3/100 -> 4226.8377 | M19: =J19*$C$3/100 -> 3097.2736 | N19: =K19*$C$3/100 -> 5356.4018
A20: 45658 | B20: 2025 Q1 | C20: 1478190.4 | D20: 1166305.8 | E20: 1790074.9 | F20: =C20*$C$3/100 -> 9661.4522 | G20: =D20*$C$3/100 -> 7622.9747 | H20: =E20*$C$3/100 -> 11699.93 | I20: 673806 | J20: 477930.44 | K20: 869681.56 | L20: =I20*$C$3/100 -> 4403.996 | M20: =J20*$C$3/100 -> 3123.7533 | N20: =K20*$C$3/100 -> 5684.2387
... A51: 48488 | B51: 2032 Q4 | C51: 4733293.1 | D51: 1868919.6 | E51: 7597666.7 | F51: =C51*$C$3/100 -> 30936.804 | G51: =D51*$C$3/100 -> 12215.258 | H51: =E51*$C$3/100 -> 49658.35 | I51: 1514061 | J51: 241530.64 | K51: 2786591.4 | L51: =I51*$C$3/100 -> 9895.9027 | M51: =J51*$C$3/100 -> 1578.6443 | N51: =K51*$C$3/100 -> 18213.161

Sheet EV historic
A2: BEV and PHEV data from 2014-2022 | E2: (quarterly data sourced from ONS)
A4: date | B4: battery | C4: hybrid | D4: mild_hybrid | E4: plugin_hybrid
A5: 41821 | B5: 10607 | C5: 180667 | D5: 13 | E5: 6284
A6: 41913 | B6: 12364 | C6: 184677 | D6: 16 | E6: 9691
A7: 42005 | B7: 14584 | C7: 194131 | D7: 17 | E7: 15447
A8: 42095 | B8: 16320 | C8: 204797 | D8: 18 | E8: 19235
A9: 42186 | B9: 18326 | C9: 216046 | D9: 20 | E9: 23334
A10: 42278 | B10: 20959 | C10: 224573 | D10: 26 | E10: 27470
A11: 42370 | B11: 23758 | C11: 237052 | D11: 34 | E11: 35468
A12: 42461 | B12: 25339 | C12: 248801 | D12: 36 | E12: 41933
A13: 42552 | B13: 27944 | C13: 262289 | D13: 32 | E13: 49007
A14: 42644 | B14: 29721 | C14: 272004 | D14: 34 | E14: 54865
A15: 42736 | B15: 33515 | C15: 290009 | D15: 51 | E15: 62784
A16: 42826 | B16: 36026 | C16: 305031 | D16: 55 | E16: 69707
... A35: 44562 | B35: 441167 | C35: 1019931 | D35: 220 | E35: 348546

Sheet Umar's EV forecast
A2: 000s unless stated | C2: Churn | D2: Age (years) | E2: 2010 | F2: 2011 | G2: 2012 | H2: 2013 | I2: 2014 | J2: 2015 | K2: 2016 | L2: 2017 | M2: 2018 | N2: 2019 | O2: 2020 | P2: 2021 | Q2: 2022 | R2: 2023 | S2: 2024 | T2: 2025 | U2: 2026 | V2: 2027 | W2: 2028 | X2: 2029 | Y2: 2030 | Z2: 2031 | AA2: 2032 | AB2: 2033 | AC2: 2034 | AD2: 2035
E3: 138 | F3: 1082 | G3: 1262 | H3: 2512 | I3: 6697 | J3: 9934 | K3: 10264 | L3: 13597 | M3: 15474 | N3: 37850 | O3: 108205 | P3: 190727 | Q3: 289000 | R3: 412000 | S3: 450000 | T3: 575000 | U3: 700000 | V3: 850000 | W3: 1000000 | X3: 1200000 | Y3: 1425000 | Z3: 1575000 | AA3: 1700000 | AB3: 1825000 | AC3: 1950000 | AD3: 2150000
E4: 111 | F4: 1056 | G4: 992 | H4: 1072 | I4: 7821 | J4: 18254 | K4: 26643 | L4: 33666 | M4: 44437 | N4: 34734 | O4: 67134 | P4: 114554 | Q4: 144000 | R4: 187000 | S4: 200000 | T4: 225000 | U4: 225000 | V4: 250000 | W4: 275000 | X4: 325000 | Y4: 325000 | Z4: 350000 | AA4: 300000 | AB4: 250000 | AC4: 150000 | AD4: 0
A5: New Car Sales | B5: EVs | E5: =SUM(E3:E4) -> 249 | F5: =SUM(F3:F4) -> 2138 | G5: =SUM(G3:G4) -> 2254 | H5: =SUM(H3:H4) -> 3584 | I5: =SUM(I3:I4) -> 14518 | J5: =SUM(J3:J4) -> 28188 | K5: =SUM(K3:K4) -> 36907 | L5: =SUM(L3:L4) -> 47263 | ... AD5: =SUM(AD3:AD4) -> 2150000
B6: Total | E6: 2030846 | F6: 1941253 | G6: 2044609 | H6: 2264737 | I6: 2476435 | J6: 2633503 | K6: 2692786 | L6: 2540617 | M6: 2367147 | N6: 2311140 | O6: 1631064 | P6: 1647181 | Q6: 1722000 | R6: 2019000 | S6: 2300000 | T6: 2300000 | U6: 2300000 | V6: 2300000 | W6: 2200000 | X6: 2100000 | Y6: 2000000 | Z6: 2100000 | AA6: 2150000 | AB6: 2175000 | AC6: 2150000 | AD6: 2150000
R7: =R5/R6 -> 0.29668153 | S7: =S5/S6 -> 0.2826087 | T7: =T5/T6 -> 0.34782609
A9: EV Car Parc (closing) | C9: =C24 -> 0.0059036214 | D9: 0-1 | E9: =E$5*(1-$C9) -> 247.53 | F9: =F$5*(1-$C9) -> 2125.3781 | G9: =G$5*(1-$C9) -> 2240.6932 | H9: =H$5*(1-$C9) -> 3562.8414 | I9: =I$5*(1-$C9) -> 14432.291 | J9: =J$5*(1-$C9) -> 28021.589 | K9: =K$5*(1-$C9) -> 36689.115 | L9: =L$5*(1-$C9) -> 46983.977 | ... AD9: =AD$5*(1-$C9) -> 2137307.2
C10: =C25 -> 0.0040923685 | D10: 1-2 | E10: 0 | F10: =E9*(1-$C10) -> 246.51701 | G10: =F9*(1-$C10) -> 2116.6802 | H10: =G9*(1-$C10) -> 2231.5235 | I10: =H9*(1-$C10) -> 3548.261 | J10: =I9*(1-$C10) -> 14373.229 | K10: =J9*(1-$C10) -> 27906.914 | L10: =K9*(1-$C10) -> 36538.97 | M10: =L9*(1-$C10) -> 46791.701 | ... AD10: =AC9*(1-$C10) -> 2079059.2
C11: =C26 -> 0.0081546451 | D11: 2-3 | E11: 0 | F11: 0 | G11: =F10*(1-$C11) -> 244.50676 | H11: =G10*(1-$C11) -> 2099.4195 | I11: =H10*(1-$C11) -> 2213.3262 | J11: =I10*(1-$C11) -> 3519.3262 | K11: =J10*(1-$C11) -> 14256.02 | L11: =K10*(1-$C11) -> 27679.343 | M11: =L10*(1-$C11) -> 36241.007 | N11: =M10*(1-$C11) -> 46410.132 | ... AD11: =AC10*(1-$C11) -> 2037556.3
C12: =C27 -> 0.011168374 | D12: 3-4 | E12: 0 | F12: 0 | G12: 0 | H12: =G11*(1-$C12) -> 241.77601 | I12: =H11*(1-$C12) -> 2075.9724 | J12: =I11*(1-$C12) -> 2188.607 | K12: =J11*(1-$C12) -> 3480.021 | L12: =K11*(1-$C12) -> 14096.804 | M12: =L11*(1-$C12) -> 27370.21 | N12: =M11*(1-$C12) -> 35836.254 | O12: =N11*(1-$C12) -> 45891.806 | ... AD12: =AC11*(1-$C12) -> 1941976
C13: =C28 -> 0.012597694 | D13: 4-5 | E13: 0 | F13: 0 | G13: 0 | H13: 0 | I13: =H12*(1-$C13) -> 238.73019 | J13: =I12*(1-$C13) -> 2049.8199 | K13: =J12*(1-$C13) -> 2161.0356 | L13: =K12*(1-$C13) -> 3436.1808 | M13: =L12*(1-$C13) -> 13919.217 | N13: =M12*(1-$C13) -> 27025.408 | O13: =N12*(1-$C13) -> 35384.8 | P13: =O12*(1-$C13) -> 45313.675 | ... AD13: =AC12*(1-$C13) -> 1845604.9
C14: =C29 -> 0.010296923 | D14: 5-6 | E14: 0 | F14: 0 | G14: 0 | H14: 0 | I14: 0 | J14: =I13*(1-$C14) -> 236.27201 | K14: =J13*(1-$C14) -> 2028.713 | L14: =K13*(1-$C14) -> 2138.7835 | M14: =L13*(1-$C14) -> 3400.7987 | N14: =M13*(1-$C14) -> 13775.891 | O14: =N13*(1-$C14) -> 26747.13 | P14: =O13*(1-$C14) -> 35020.445 | Q14: =P13*(1-$C14) -> 44847.084 | ... AD14: =AC13*(1-$C14) -> 1660546.2
C15: =C30 -> 0.010185744 | D15: 6-7 | E15: 0 | F15: 0 | G15: 0 | H15: 0 | I15: 0 | J15: 0 | K15: =J14*(1-$C15) -> 233.8654 | L15: =K14*(1-$C15) -> 2008.0491 | M15: =L14*(1-$C15) -> 2116.9984 | N15: =M14*(1-$C15) -> 3366.159 | O15: =N14*(1-$C15) -> 13635.574 | P15: =O14*(1-$C15) -> 26474.69 | Q15: =P14*(1-$C15) -> 34663.736 | R15: =Q14*(1-$C15) -> 44390.283 | ... AD15: =AC14*(1-$C15) -> 1432308.2
C16: =C31 -> 0.012319736 | D16: 7-8 | E16: 0 | F16: 0 | G16: 0 | H16: 0 | I16: 0 | J16: 0 | K16: 0 | L16: =K15*(1-$C16) -> 230.98424 | M16: =L15*(1-$C16) -> 1983.3105 | N16: =M15*(1-$C16) -> 2090.9176 | O16: =N15*(1-$C16) -> 3324.6888 | P16: =O15*(1-$C16) -> 13467.587 | Q16: =P15*(1-$C16) -> 26148.529 | R16: =Q15*(1-$C16) -> 34236.688 | S16: =R15*(1-$C16) -> 43843.406 | ... AD16: =AC15*(1-$C16) -> 1182750.6
C17: =C32 -> 0.016547657 | D17: 8-9 | E17: 0 | F17: 0 | G17: 0 | H17: 0 | I17: 0 | J17: 0 | K17: 0 | L17: 0 | M17: =L16*(1-$C17) -> 227.16199 | N17: =M16*(1-$C17) -> 1950.4913 | O17: =N16*(1-$C17) -> 2056.3178 | P17: =O16*(1-$C17) -> 3269.673 | Q17: =P16*(1-$C17) -> 13244.73 | R17: =Q16*(1-$C17) -> 25715.832 | S17: =R16*(1-$C17) -> 33670.151 | T17: =S16*(1-$C17) -> 43117.901 | ... AD17: =AC16*(1-$C17) -> 1003526.9
C18: =C33 -> 0.021708557 | D18: 9-10 | E18: 0 | F18: 0 | G18: 0 | H18: 0 | I18: 0 | J18: 0 | K18: 0 | L18: 0 | M18: 0 | N18: =M17*(1-$C18) -> 222.23063 | O18: =N17*(1-$C18) -> 1908.149 | P18: =O17*(1-$C18) -> 2011.6781 | Q18: =P17*(1-$C18) -> 3198.6931 | R18: =Q17*(1-$C18) -> 12957.206 | S18: =R17*(1-$C18) -> 25157.579 | T18: =S17*(1-$C18) -> 32939.221 | U18: =T17*(1-$C18) -> 42181.873 | ... AD18: =AC17*(1-$C18) -> 825555.56
C19: =C34 -> 0.021708557 | D19: 10+ | E19: 0 | F19: 0 | G19: 0 | H19: 0 | I19: 0 | J19: 0 | K19: 0 | L19: 0 | M19: 0 | N19: 0 | O19: =N18*(1-$C19) -> 217.40633 | P19: =O18*(1-$C19) -> 1866.7258 | Q19: =P18*(1-$C19) -> 1968.0075 | R19: =Q18*(1-$C19) -> 3129.2541 | S19: =R18*(1-$C19) -> 12675.924 | T19: =S18*(1-$C19) -> 24611.444 | U19: =T18*(1-$C19) -> 32224.158 | V19: =U18*(1-$C19) -> 41266.166 | ... AD19: =AC18*(1-$C19) -> 698494.22
D20: Total | E20: =SUM(E9:E19) -> 247.53 | F20: =SUM(F9:F19) -> 2371.8951 | G20: =SUM(G9:G19) -> 4601.8802 | H20: =SUM(H9:H19) -> 8135.5604 | I20: =SUM(I9:I19) -> 22508.581 | J20: =SUM(J9:J19) -> 50388.843 | K20: =SUM(K9:K19) -> 86755.684 | L20: =SUM(L9:L19) -> 133113.09 | ... AD20: =SUM(AD9:AD19) -> 16844685
C21: Closing EV Parc per ACEA | J21: =0.4%*J35 -> 134169.79 | K21: =0.2%*K35 -> 68756.772 | M21: =0.4%*M35 -> 139551.66 | N21: =0.7%*N35 -> 246177.81 | O21: =1.1%*O35 -> 401001.32
A24: Total Car Parc (closing) | C24: =AVERAGE(J37:N37) -> 0.0059036214 | D24: 0-1 | J24: 2622550 | K24: 2679763 | M24: 2347530 | N24: 2296506 | O24: 1646250 | P24: =P$6*(1-$C24) -> 1637456.7 | Q24: =Q$6*(1-$C24) -> 1711834 | R24: =R$6*(1-$C24) -> 2007080.6 | S24: =S$6*(1-$C24) -> 2286421.7 | T24: =T$6*(1-$C24) -> 2286421.7 | U24: =U$6*(1-$C24) -> 2286421.7 | V24: =V$6*(1-$C24) -> 2286421.7 | W24: =W$6*(1-$C24) -> 2187012 | ... AD24: =AD$6*(1-$C24) -> 2137307.2
C25: =AVERAGE(J38:N38) -> 0.0040923685 | D25: 1-2 | J25: 2459044 | K25: 2616513 | M25: 2510711 | N25: 2333720 | O25: 2276500 | P25: =O24*(1-$C25) -> 1639512.9 | Q25: =P24*(1-$C25) -> 1630755.6 | R25: =Q24*(1-$C25) -> 1704828.5 | S25: =R24*(1-$C25) -> 1998866.9 | T25: =S24*(1-$C25) -> 2277064.8 | U25: =T24*(1-$C25) -> 2277064.8 | V25: =U24*(1-$C25) -> 2277064.8 | W25: =V24*(1-$C25) -> 2277064.8 | ... AD25: =AC24*(1-$C25) -> 2128560.6
C26: =AVERAGE(J39:N39) -> 0.0081546451 | D26: 2-3 | J26: 2229797 | K26: 2443580 | M26: 2646155 | N26: 2485552 | O26: 2288133 | P26: =O25*(1-$C26) -> 2257936 | Q26: =P25*(1-$C26) -> 1626143.3 | R26: =Q25*(1-$C26) -> 1617457.4 | S26: =R25*(1-$C26) -> 1690926.2 | T26: =S25*(1-$C26) -> 1982566.8 | U26: =T25*(1-$C26) -> 2258496.1 | V26: =U25*(1-$C26) -> 2258496.1 | W26: =V25*(1-$C26) -> 2258496.1 | ... AD26: =AC25*(1-$C26) -> 2135751.8
C27: =AVERAGE(J40:N40) -> 0.011168374 | D27: 3-4 | J27: 1984883 | K27: 2209963 | M27: 2562657 | N27: 2610586 | O27: 2372755 | P27: =O26*(1-$C27) -> 2262578.3 | Q27: =P26*(1-$C27) -> 2232718.5 | R27: =Q26*(1-$C27) -> 1607981.9 | S27: =R26*(1-$C27) -> 1599393 | T27: =S26*(1-$C27) -> 1672041.3 | U27: =T26*(1-$C27) -> 1960424.8 | V27: =U26*(1-$C27) -> 2233272.4 | W27: =V26*(1-$C27) -> 2233272.4 | ... AD27: =AC26*(1-$C27) -> 2087624.2
C28: =AVERAGE(J41:N41) -> 0.012597694 | D28: 4-5 | J28: 1860448 | K28: 1963985 | M28: 2379064 | N28: 2525071 | O28: 2539709 | P28: =O27*(1-$C28) -> 2342863.8 | Q28: =P27*(1-$C28) -> 2234075 | R28: =Q27*(1-$C28) -> 2204591.4 | S28: =R27*(1-$C28) -> 1587725.1 | T28: =S27*(1-$C28) -> 1579244.3 | U28: =T27*(1-$C28) -> 1650977.5 | V28: =U27*(1-$C28) -> 1935727.9 | W28: =V27*(1-$C28) -> 2205138.3 | ... AD28: =AC27*(1-$C28) -> 2013387.2
C29: =AVERAGE(J42:N42) -> 0.010296923 | D29: 5-6 | J29: 1935386 | K29: 1842529 | M29: 2156326 | N29: 2352984 | O29: 2470111 | P29: =O28*(1-$C29) -> 2513557.8 | Q29: =P28*(1-$C29) -> 2318739.5 | R29: =Q28*(1-$C29) -> 2211070.9 | S29: =R28*(1-$C29) -> 2181890.9 | T29: =S28*(1-$C29) -> 1571376.4 | U29: =T28*(1-$C29) -> 1562983 | V29: =U28*(1-$C29) -> 1633977.5 | W29: =V28*(1-$C29) -> 1915795.9 | ... AD29: =AC28*(1-$C29) -> 1897767.1
C30: =AVERAGE(J43:N43) -> 0.010185744 | D30: 6-7 | J30: 1898716 | K30: 1917222 | M30: 1919838 | N30: 2132636 | O30: 2297801 | P30: =O29*(1-$C30) -> 2444951.1 | Q30: =P29*(1-$C30) -> 2487955.4 | R30: =Q29*(1-$C30) -> 2295121.4 | S30: =R29*(1-$C30) -> 2188549.5 | T30: =S29*(1-$C30) -> 2159666.7 | U30: =T29*(1-$C30) -> 1555370.7 | V30: =U29*(1-$C30) -> 1547062.8 | W30: =V29*(1-$C30) -> 1617334.2 | ... AD30: =AC29*(1-$C30) -> 1972358.8
C31: =AVERAGE(J44:N44) -> 0.012319736 | D31: 7-8 | J31: 1995199 | K31: 1877340 | M31: 1795516 | N31: 1894148 | O31: 2084332 | P31: =O30*(1-$C31) -> 2269492.7 | Q31: =P30*(1-$C31) -> 2414829.9 | R31: =Q30*(1-$C31) -> 2457304.4 | S31: =R30*(1-$C31) -> 2266846.1 | T31: =S30*(1-$C31) -> 2161587.2 | U31: =T30*(1-$C31) -> 2133060.2 | V31: =U30*(1-$C31) -> 1536209 | W31: =V30*(1-$C31) -> 1528003.4 | ... AD31: =AC30*(1-$C31) -> 2040824.6
C32: =AVERAGE(J45:N45) -> 0.016547657 | D32: 8-9 | J32: 2260520 | K32: 1962957 | M32: 1860000 | N32: 1765108 | O32: 1850516 | P32: =O31*(1-$C32) -> 2049841.2 | Q32: =P31*(1-$C32) -> 2231937.9 | R32: =Q31*(1-$C32) -> 2374870.2 | S32: =R31*(1-$C32) -> 2416641.8 | T32: =S31*(1-$C32) -> 2229335.1 | U32: =T31*(1-$C32) -> 2125818 | V32: =U31*(1-$C32) -> 2097763 | W32: =V31*(1-$C32) -> 1510788.3 | ... AD32: =AC31*(1-$C32) -> 2098283.5
C33: =AVERAGE(J46:N46) -> 0.021708557 | D33: 9-10 | J33: 2145040 | K33: 2211394 | M33: 1804086 | N33: 1819666 | O33: 1717777 | P33: =O32*(1-$C33) -> 1810344 | Q33: =P32*(1-$C33) -> 2005342.1 | R33: =Q32*(1-$C33) -> 2183485.8 | S33: =R32*(1-$C33) -> 2323315.2 | T33: =S32*(1-$C33) -> 2364180 | U33: =T32*(1-$C33) -> 2180939.5 | V33: =U32*(1-$C33) -> 2079669.5 | W33: =V32*(1-$C33) -> 2052223.6 | ... AD33: =AC32*(1-$C33) -> 2052732.8
C34: =C33 -> 0.021708557 | D34: 10+ | J34: 12150865 | K34: 12653140 | M34: 12906032 | N34: 12952282 | O34: 14910781 | P34: =O33*(1-$C34) -> 1680486.5 | Q34: =P33*(1-$C34) -> 1771044 | R34: =Q33*(1-$C34) -> 1961809 | S34: =R33*(1-$C34) -> 2136085.4 | T34: =S33*(1-$C34) -> 2272879.3 | U34: =T33*(1-$C34) -> 2312857 | V34: =U33*(1-$C34) -> 2133594.4 | W34: =V33*(1-$C34) -> 2034522.9 | ... AD34: =AC33*(1-$C34) -> 2008170.9
D35: Total | E35: =SUM(E24:E34) -> 0 | F35: =SUM(F24:F34) -> 0 | G35: =SUM(G24:G34) -> 0 | H35: =SUM(H24:H34) -> 0 | I35: =SUM(I24:I34) -> 0 | J35: =SUM(J24:J34) -> 33542448 | K35: =SUM(K24:K34) -> 34378386 | L35: =SUM(L24:L34) -> 0 | ... AD35: =SUM(AD24:AD34) -> 22572769
A37: Churn | D37: 0-1 | J37: =1-J24/J6 -> 0.0041590991 | K37: =1-K24/K6 -> 0.0048362551 | M37: =1-M24/M6 -> 0.0082871913 | N37: =1-N24/N6 -> 0.0063319401 | O37: =1-O24/O6 -> -0.0093104869
D38: 1-2 | K38: =1-K25/J24 -> 0.002301958 | N38: =1-N25/M24 -> 0.0058827789 | O38: =1-O25/N24 -> 0.0087114948
D39: 2-3 | K39: =1-K26/J25 -> 0.0062886227 | N39: =1-N26/M25 -> 0.010020667 | O39: =1-O26/N25 -> 0.019534049
D40: 3-4 | K40: =1-K27/J26 -> 0.0088949801 | N40: =1-N27/M26 -> 0.013441767 | O40: =1-O27/N26 -> 0.045381066
D41: 4-5 | K41: =1-K28/J27 -> 0.01052858 | N41: =1-N28/M27 -> 0.014666809 | O41: =1-O28/N27 -> 0.027149843
D42: 5-6 | K42: =1-K29/J28 -> 0.0096315511 | N42: =1-N29/M28 -> 0.010962294 | O42: =1-O29/N28 -> 0.021765725
D43: 6-7 | K43: =1-K30/J29 -> 0.0093852079 | N43: =1-N30/M29 -> 0.010986279 | O43: =1-O30/N29 -> 0.023452348
D44: 7-8 | K44: =1-K31/J30 -> 0.011258134 | N44: =1-N31/M30 -> 0.013381337 | O44: =1-O31/N30 -> 0.022649904
D45: 8-9 | K45: =1-K32/J31 -> 0.016159792 | N45: =1-N32/M31 -> 0.016935522 | O45: =1-O32/N31 -> 0.023035159
...

Sheet branch forecasts
B1: Brunting | C1: Bristol | D1: Vehicle Solutions Leeds | E1: Leeds | F1: Colchester | G1: Wimbledon | H1: Vehicle Solutions Coventry | I1: Manchester | J1: Plymouth | K1: Washington | L1: Northampton | M1: Mansfield | N1: Shotts | O1: ManheimOnline | P1: Birmingham | Q1: Gloucester | R1: Haydock
B2: 184 | C2: 117 | D2: 113 | E2: 99 | F2: 85 | G2: 47 | H2: 44 | I2: 37 | J2: 32 | K2: 25 | L2: 23 | M2: 19 | N2: 18 | O2: 12 | P2: 10 | Q2: 4 | R2: 3 | S2: =SUM(B2:R2) -> 872
A3: =B2*100/$S$2 -> 21.100917 | B3: =C2*100/$S$2 -> 13.417431 | C3: =D2*100/$S$2 -> 12.958716 | D3: =E2*100/$S$2 -> 11.353211 | E3: =F2*100/$S$2 -> 9.7477064 | F3: =G2*100/$S$2 -> 5.3899083 | G3: =H2*100/$S$2 -> 5.0458716 | H3: =I2*100/$S$2 -> 4.2431193 | ... Q3: =R2*100/$S$2 -> 0.3440367
A4: Percent of Total | B4: 21.100917 | C4: 13.417431 | D4: 12.958716 | E4: 11.353211 | F4: 9.7477064 | G4: 5.3899083 | H4: 5.0458716 | I4: 4.2431193 | J4: 3.6697248 | K4: 2.8669725 | L4: 2.6376147 | M4: 2.1788991 | N4: 2.0642202 | O4: 1.3761468 | P4: 1.146789 | Q4: 0.4587156 | R4: 0.3440367
A7: Branch Forecasts
A9: Year | B9: Brunting | C9: Bristol | D9: Vehicle Solutions Leeds | E9: Leeds | F9: Colchester | G9: Wimbledon | H9: Vehicle Solutions Coventry | I9: Manchester | J9: Plymouth | K9: Washington | L9: Northampton | M9: Mansfield | N9: Shotts | O9: ManheimOnline | P9: Birmingham | Q9: Gloucester | R9: Haydock
A10: 2022 | B10: =B4*$S$10/100 -> 1506.7375 | C10: =C4*$S$10/100 -> 958.08851 | D10: =D4*$S$10/100 -> 925.33335 | E10: =E4*$S$10/100 -> 810.69028 | F10: =F4*$S$10/100 -> 696.04721 | G10: =G4*$S$10/100 -> 384.87316 | H10: =H4*$S$10/100 -> 360.30679 | I10: =I4*$S$10/100 -> 302.98526 | ... R10: =R4*$S$10/100 -> 24.566372 | S10: 7140.6255
A11: 2023 | B11: =B4*$S$11/100 -> 2127.4134 | C11: =C4*$S$11/100 -> 1352.7574 | D11: =D4*$S$11/100 -> 1306.5093 | E11: =E4*$S$11/100 -> 1144.6409 | F11: =F4*$S$11/100 -> 982.77249 | G11: =G4*$S$11/100 -> 543.41538 | H11: =H4*$S$11/100 -> 508.72929 | I11: =I4*$S$11/100 -> 427.79508 | ... R11: =R4*$S$11/100 -> 34.686088 | S11: 10082.09
A12: 2024 | B12: =B4*$S$12/100 -> 2796.1792 | C12: =C4*$S$12/100 -> 1778.0052 | D12: =D4*$S$12/100 -> 1717.2187 | E12: =E4*$S$12/100 -> 1504.466 | F12: =F4*$S$12/100 -> 1291.7132 | G12: =G4*$S$12/100 -> 714.24142 | H12: =H4*$S$12/100 -> 668.65154 | I12: =I4*$S$12/100 -> 562.27516 | ... R12: =R4*$S$12/100 -> 45.589878 | S12: 13251.458
A13: 2025 | B13: =B4*$S$13/100 -> 3493.7699 | C13: =C4*$S$13/100 -> 2221.5819 | D13: =D4*$S$13/100 -> 2145.6304 | E13: =E4*$S$13/100 -> 1879.8001 | F13: =F4*$S$13/100 -> 1613.9698 | G13: =G4*$S$13/100 -> 892.43035 | H13: =H4*$S$13/100 -> 835.46671 | I13: =I4*$S$13/100 -> 702.55155 | ... R13: =R4*$S$13/100 -> 56.963639 | S13: 16557.431
A14: 2026 | B14: =B4*$S$14/100 -> 4208.6384 | C14: =C4*$S$14/100 -> 2676.145 | D14: =D4*$S$14/100 -> 2584.6529 | E14: =E4*$S$14/100 -> 2264.4304 | F14: =F4*$S$14/100 -> 1944.2079 | G14: =G4*$S$14/100 -> 1075.0326 | H14: =H4*$S$14/100 -> 1006.4135 | I14: =I4*$S$14/100 -> 846.30228 | ... R14: =R4*$S$14/100 -> 68.619104 | S14: 19945.286
A15: 2027 | B15: =B4*$S$15/100 -> 4933.8632 | C15: =C4*$S$15/100 -> 3137.2935 | D15: =D4*$S$15/100 -> 3030.0356 | E15: =E4*$S$15/100 -> 2654.6329 | F15: =F4*$S$15/100 -> 2279.2303 | G15: =G4*$S$15/100 -> 1260.2803 | H15: =H4*$S$15/100 -> 1179.8369 | I15: =I4*$S$15/100 -> 992.13554 | ... R15: =R4*$S$15/100 -> 80.443422 | S15: 23382.221
A16: 2028 | B16: =B4*$S$16/100 -> 5665.2958 | C16: =C4*$S$16/100 -> 3602.3892 | D16: =D4*$S$16/100 -> 3479.2306 | E16: =E4*$S$16/100 -> 3048.1755 | F16: =F4*$S$16/100 -> 2617.1203 | G16: =G4*$S$16/100 -> 1447.1136 | H16: =H4*$S$16/100 -> 1354.7446 | I16: =I4*$S$16/100 -> 1139.2171 | ... R16: =R4*$S$16/100 -> 92.368953 | S16: 26848.576
A17: 2029 | B17: =B4*$S$17/100 -> 6400.4493 | C17: =C4*$S$17/100 -> 4069.8509 | D17: =D4*$S$17/100 -> 3930.7107 | E17: =E4*$S$17/100 -> 3443.72 | F17: =F4*$S$17/100 -> 2956.7293 | G17: =G4*$S$17/100 -> 1634.8974 | H17: =H4*$S$17/100 -> 1530.5422 | I17: =I4*$S$17/100 -> 1287.0469 | ... R17: =R4*$S$17/100 -> 104.35515 | S17: 30332.564
A18: 2030 | B18: =B4*$S$18/100 -> 7137.8331 | C18: =C4*$S$18/100 -> 4538.7308 | D18: =D4*$S$18/100 -> 4383.5605 | E18: =E4*$S$18/100 -> 3840.4645 | F18: =F4*$S$18/100 -> 3297.3685 | G18: =G4*$S$18/100 -> 1823.2508 | H18: =H4*$S$18/100 -> 1706.8731 | I18: =I4*$S$18/100 -> 1435.3251 | ... R18: =R4*$S$18/100 -> 116.37771 | S18: 33827.122
A19: 2031 | B19: =B4*$S$19/100 -> 7876.5537 | C19: =C4*$S$19/100 -> 5008.4608 | D19: =D4*$S$19/100 -> 4837.2314 | E19: =E4*$S$19/100 -> 4237.9284 | F19: =F4*$S$19/100 -> 3638.6254 | G19: =G4*$S$19/100 -> 2011.9458 | H19: =H4*$S$19/100 -> 1883.5237 | I19: =I4*$S$19/100 -> 1583.8722 | ... R19: =R4*$S$19/100 -> 128.42207 | S19: 37328.015
A20: 2032 | B20: =B4*$S$20/100 -> 8616.0757 | C20: =C4*$S$20/100 -> 5478.7003 | D20: =D4*$S$20/100 -> 5291.3943 | E20: =E4*$S$20/100 -> 4635.8233 | F20: =F4*$S$20/100 -> 3980.2524 | G20: =G4*$S$20/100 -> 2200.8454 | H20: =H4*$S$20/100 -> 2060.3659 | I20: =I4*$S$20/100 -> 1732.5804 | ... R20: =R4*$S$20/100 -> 140.4795 | S20: 40832.707
A22: Year | B22: Brunting | C22: Bristol | D22: Vehicle Solutions Leeds | E22: Leeds | F22: Colchester | G22: Wimbledon | H22: Vehicle Solutions Coventry | I22: Manchester | J22: Plymouth | K22: Washington | L22: Northampton | M22: Mansfield | N22: Shotts | O22: ManheimOnline | P22: Birmingham | Q22: Gloucester | R22: Haydock
A23: 2022 | B23: =S23*$B$4/100 -> 1595.5387 | C23: =S23*$C$4/100 -> 1014.5545 | D23: =S23*$D$4/100 -> 979.86886 | E23: =S23*$E$4/100 -> 858.46918 | F23: =S23*$F$4/100 -> 737.0695 | G23: =S23*$G$4/100 -> 407.55607 | H23: =S23*$H$4/100 -> 381.54186 | I23: =S23*$I$4/100 -> 320.84202 | J23: =S23*$J$4/100 -> 277.48499 | K23: =S23*$K$4/100 -> 216.78515 | L23: =S23*$L$4/100 -> 199.44233 | M23: =S23*$M$4/100 -> 164.75671 | N23: =S23*$N$4/100 -> 156.0853 | O23: =S23*$O$4/100 -> 104.05687 | P23: =S23*$P$4/100 -> 86.714058 | Q23: =S23*$Q$4/100 -> 34.685623 | R23: =S23*$R$4/100 -> 26.014217 | S23: 7561.4659
A24: 2023 | B24: =S24*$B$4/100 -> 2424.6843 | C24: =S24*$C$4/100 -> 1541.783 | D24: =S24*$D$4/100 -> 1489.0724 | E24: =S24*$E$4/100 -> 1304.5856 | F24: =S24*$F$4/100 -> 1120.0987 | G24: =S24*$G$4/100 -> 619.34871 | H24: =S24*$H$4/100 -> 579.81582 | I24: =S24*$I$4/100 -> 487.57239 | J24: =S24*$J$4/100 -> 421.68423 | K24: =S24*$K$4/100 -> 329.4408 | L24: =S24*$L$4/100 -> 303.08554 | M24: =S24*$M$4/100 -> 250.37501 | N24: =S24*$N$4/100 -> 237.19738 | O24: =S24*$O$4/100 -> 158.13159 | P24: =S24*$P$4/100 -> 131.77632 | Q24: =S24*$Q$4/100 -> 52.710529 | R24: =S24*$R$4/100 -> 39.532897 | S24: 11490.895
A25: 2024 | B25: =S25*$B$4/100 -> 3404.6272 | C25: =S25*$C$4/100 -> 2164.8988 | D25: =S25*$D$4/100 -> 2090.8852 | E25: =S25*$E$4/100 -> 1831.8375 | F25: =S25*$F$4/100 -> 1572.7897 | G25: =S25*$G$4/100 -> 869.66021 | H25: =S25*$H$4/100 -> 814.14998 | I25: =S25*$I$4/100 -> 684.62612 | J25: =S25*$J$4/100 -> 592.10908 | K25: =S25*$K$4/100 -> 462.58522 | L25: =S25*$L$4/100 -> 425.5784 | M25: =S25*$M$4/100 -> 351.56476 | N25: =S25*$N$4/100 -> 333.06136 | O25: =S25*$O$4/100 -> 222.0409 | P25: =S25*$P$4/100 -> 185.03409 | Q25: =S25*$Q$4/100 -> 74.013635 | R25: =S25*$R$4/100 -> 55.510226 | S25: 16134.972
A26: 2025 | B26: =S26*$B$4/100 -> 4504.2449 | C26: =S26*$C$4/100 -> 2864.1123 | D26: =S26*$D$4/100 -> 2766.1939 | E26: =S26*$E$4/100 -> 2423.4796 | F26: =S26*$F$4/100 -> 2080.7653 | G26: =S26*$G$4/100 -> 1150.5408 | H26: =S26*$H$4/100 -> 1077.102 | I26: =S26*$I$4/100 -> 905.7449 | J26: =S26*$J$4/100 -> 783.34694 | K26: =S26*$K$4/100 -> 611.9898 | L26: =S26*$L$4/100 -> 563.03061 | M26: =S26*$M$4/100 -> 465.11225 | N26: =S26*$N$4/100 -> 440.63266 | O26: =S26*$O$4/100 -> 293.7551 | P26: =S26*$P$4/100 -> 244.79592 | Q26: =S26*$Q$4/100 -> 97.918368 | R26: =S26*$R$4/100 -> 73.438776 | S26: 21346.204
A27: 2026 | B27: =S27*$B$4/100 -> 5701.9363 | C27: =S27*$C$4/100 -> 3625.6878 | D27: =S27*$D$4/100 -> 3501.7326 | E27: =S27*$E$4/100 -> 3067.8897 | F27: =S27*$F$4/100 -> 2634.0467 | G27: =S27*$G$4/100 -> 1456.4729 | H27: =S27*$H$4/100 -> 1363.5065 | I27: =S27*$I$4/100 -> 1146.585 | J27: =S27*$J$4/100 -> 991.6411 | K27: =S27*$K$4/100 -> 774.71961 | L27: =S27*$L$4/100 -> 712.74204 | M27: =S27*$M$4/100 -> 588.7869 | N27: =S27*$N$4/100 -> 557.79812 | O27: =S27*$O$4/100 -> 371.86541 | P27: =S27*$P$4/100 -> 309.88784 | Q27: =S27*$Q$4/100 -> 123.95514 | R27: =S27*$R$4/100 -> 92.966353 | S27: 27022.22
A28: 2027 | B28: =S28*$B$4/100 -> 6982.3521 | C28: =S28*$C$4/100 -> 4439.8652 | D28: =S28*$D$4/100 -> 4288.075 | E28: =S28*$E$4/100 -> 3756.809 | F28: =S28*$F$4/100 -> 3225.5431 | G28: =S28*$G$4/100 -> 1783.5356 | H28: =S28*$H$4/100 -> 1669.6929 | I28: =S28*$I$4/100 -> 1404.0599 | J28: =S28*$J$4/100 -> 1214.3221 | K28: =S28*$K$4/100 -> 948.68915 | L28: =S28*$L$4/100 -> 872.79402 | M28: =S28*$M$4/100 -> 721.00375 | N28: =S28*$N$4/100 -> 683.05619 | O28: =S28*$O$4/100 -> 455.37079 | P28: =S28*$P$4/100 -> 379.47566 | Q28: =S28*$Q$4/100 -> 151.79026 | R28: =S28*$R$4/100 -> 113.8427 | S28: 33090.278
A29: 2028 | B29: =S29*$B$4/100 -> 8334.3861 | C29: =S29*$C$4/100 -> 5299.5824 | D29: =S29*$D$4/100 -> 5118.4001 | E29: =S29*$E$4/100 -> 4484.2621 | F29: =S29*$F$4/100 -> 3850.124 | G29: =S29*$G$4/100 -> 2128.8921 | H29: =S29*$H$4/100 -> 1993.0054 | I29: =S29*$I$4/100 -> 1675.9363 | J29: =S29*$J$4/100 -> 1449.4584 | K29: =S29*$K$4/100 -> 1132.3894 | L29: =S29*$L$4/100 -> 1041.7983 | M29: =S29*$M$4/100 -> 860.61595 | N29: =S29*$N$4/100 -> 815.32038 | O29: =S29*$O$4/100 -> 543.54692 | P29: =S29*$P$4/100 -> 452.95576 | Q29: =S29*$Q$4/100 -> 181.18231 | R29: =S29*$R$4/100 -> 135.88673 | S29: 39497.743
A30: 2029 | B30: =S30*$B$4/100 -> 9749.8405 | C30: =S30*$C$4/100 -> 6199.6268 | D30: =S30*$D$4/100 -> 5987.6738 | E30: =S30*$E$4/100 -> 5245.8381 | F30: =S30*$F$4/100 -> 4504.0024 | G30: =S30*$G$4/100 -> 2490.4484 | H30: =S30*$H$4/100 -> 2331.4836 | I30: =S30*$I$4/100 -> 1960.5657 | J30: =S30*$J$4/100 -> 1695.6244 | K30: =S30*$K$4/100 -> 1324.7066 | L30: =S30*$L$4/100 -> 1218.7301 | M30: =S30*$M$4/100 -> 1006.777 | N30: =S30*$N$4/100 -> 953.78874 | O30: =S30*$O$4/100 -> 635.85916 | P30: =S30*$P$4/100 -> 529.88263 | Q30: =S30*$Q$4/100 -> 211.95305 | R30: =S30*$R$4/100 -> 158.96479 | S30: 46205.766
A31: 2030 | B31: =S31*$B$4/100 -> 11222.53 | C31: =S31*$C$4/100 -> 7136.0654 | D31: =S31*$D$4/100 -> 6892.0974 | E31: =S31*$E$4/100 -> 6038.2092 | F31: =S31*$F$4/100 -> 5184.321 | G31: =S31*$G$4/100 -> 2866.6246 | H31: =S31*$H$4/100 -> 2683.6485 | I31: =S31*$I$4/100 -> 2256.7044 | J31: =S31*$J$4/100 -> 1951.7444 | K31: =S31*$K$4/100 -> 1524.8003 | L31: =S31*$L$4/100 -> 1402.8163 | M31: =S31*$M$4/100 -> 1158.8482 | N31: =S31*$N$4/100 -> 1097.8562 | O31: =S31*$O$4/100 -> 731.90415 | P31: =S31*$P$4/100 -> 609.92012 | Q31: =S31*$Q$4/100 -> 243.96805 | R31: =S31*$R$4/100 -> 182.97604 | S31: 53185.035
A32: 2031 | B32: =S32*$B$4/100 -> 12747.679 | C32: =S32*$C$4/100 -> 8105.8612 | D32: =S32*$D$4/100 -> 7828.7377 | E32: =S32*$E$4/100 -> 6858.8056 | F32: =S32*$F$4/100 -> 5888.8735 | G32: =S32*$G$4/100 -> 3256.2006 | H32: =S32*$H$4/100 -> 3048.358 | I32: =S32*$I$4/100 -> 2563.392 | J32: =S32*$J$4/100 -> 2216.9877 | K32: =S32*$K$4/100 -> 1732.0216 | L32: =S32*$L$4/100 -> 1593.4599 | M32: =S32*$M$4/100 -> 1316.3364 | N32: =S32*$N$4/100 -> 1247.0556 | O32: =S32*$O$4/100 -> 831.37037 | P32: =S32*$P$4/100 -> 692.80865 | Q32: =S32*$Q$4/100 -> 277.12346 | R32: =S32*$R$4/100 -> 207.84259 | S32: 60412.914
A33: 2032 | B33: =S33*$B$4/100 -> 14321.511 | C33: =S33*$C$4/100 -> 9106.6132 | D33: =S33*$D$4/100 -> 8795.276 | E33: =S33*$E$4/100 -> 7705.5958 | F33: =S33*$F$4/100 -> 6615.9156 | G33: =S33*$G$4/100 -> 3658.2122 | H33: =S33*$H$4/100 -> 3424.7093 | I33: =S33*$I$4/100 -> 2879.8691 | J33: =S33*$J$4/100 -> 2490.6976 | K33: =S33*$K$4/100 -> 1945.8575 | L33: =S33*$L$4/100 -> 1790.1889 | M33: =S33*$M$4/100 -> 1478.8517 | N33: =S33*$N$4/100 -> 1401.0174 | O33: =S33*$O$4/100 -> 934.01161 | P33: =S33*$P$4/100 -> 778.34301 | Q33: =S33*$Q$4/100 -> 311.3372 | R33: =S33*$R$4/100 -> 233.5029 | S33: 67871.511

Sheet PHEV and BEV volumes
B1: Brunting | C1: Bristol | D1: Vehicle Solutions Leeds | E1: Leeds | F1: Colchester | G1: Wimbledon | H1: Vehicle Solutions Coventry | I1: Manchester | J1: Plymouth | K1: Washington | L1: Northampton | M1: Mansfield | N1: Shotts | O1: ManheimOnline | P1: Birmingham | Q1: Gloucester | R1: Haydock
B2: 184 | C2: 117 | D2: 113 | E2: 99 | F2: 85 | G2: 47 | H2: 44 | I2: 37 | J2: 32 | K2: 25 | L2: 23 | M2: 19 | N2: 18 | O2: 12 | P2: 10 | Q2: 4 | R2: 3 | S2: =SUM(B2:R2) -> 872
B3: =B2/S2 -> 0.21100917 | R3: =R2/S2 -> 0.003440367
A4: Percent of Total | B4: 21.100917 | C4: 13.417431 | D4: 12.958716 | E4: 11.353211 | F4: 9.7477064 | G4: 5.3899083 | H4: 5.0458716 | I4: 4.2431193 | J4: 3.6697248 | K4: 2.8669725 | L4: 2.6376147 | M4: 2.1788991 | N4: 2.0642202 | O4: 1.3761468 | P4: 1.146789 | Q4: 0.4587156 | R4: 0.3440367
A7: PHEV - MID
A8: Year | B8: Brunting | C8: Bristol | D8: Vehicle Solutions Leeds | E8: Leeds | F8: Colchester | G8: Wimbledon | H8: Vehicle Solutions Coventry | I8: Manchester | J8: Plymouth | K8: Washington | L8: Northampton | M8: Mansfield | N8: Shotts | O8: ManheimOnline | P8: Birmingham | Q8: Gloucester | R8: Haydock
A9: 2022 | B9: =S9*$B$4/100 -> 592.84536 | C9: =S9*$C$4/100 -> 376.97232 | D9: =S9*$D$4/100 -> 364.08438 | E9: =S9*$E$4/100 -> 318.97658 | F9: =S9*$F$4/100 -> 273.86878 | G9: =S9*$G$4/100 -> 151.43333 | H9: =S9*$H$4/100 -> 141.76737 | I9: =S9*$I$4/100 -> 119.21347 | J9: =S9*$J$4/100 -> 103.10354 | K9: =S9*$K$4/100 -> 80.549642 | L9: =S9*$L$4/100 -> 74.10567 | M9: =S9*$M$4/100 -> 61.217728 | N9: =S9*$N$4/100 -> 57.995742 | O9: =S9*$O$4/100 -> 38.663828 | P9: =S9*$P$4/100 -> 32.219857 | Q9: =S9*$Q$4/100 -> 12.887943 | R9: =S9*$R$4/100 -> 9.665957 | S9: 2809.5715
A10: 2023 | B10: =S10*$B$4/100 -> 742.37345 | C10: =S10*$C$4/100 -> 472.05268 | D10: =S10*$D$4/100 -> 455.91413 | E10: =S10*$E$4/100 -> 399.42919 | F10: =S10*$F$4/100 -> 342.94426 | G10: =S10*$G$4/100 -> 189.628 | H10: =S10*$H$4/100 -> 177.52409 | I10: =S10*$I$4/100 -> 149.28162 | J10: =S10*$J$4/100 -> 129.10843 | K10: =S10*$K$4/100 -> 100.86596 | L10: =S10*$L$4/100 -> 92.796681 | M10: =S10*$M$4/100 -> 76.658128 | N10: =S10*$N$4/100 -> 72.62349 | O10: =S10*$O$4/100 -> 48.41566 | P10: =S10*$P$4/100 -> 40.346383 | Q10: =S10*$Q$4/100 -> 16.138553 | R10: =S10*$R$4/100 -> 12.103915 | S10: 3518.2046
A11: 2024 | B11: =S11*$B$4/100 -> 891.90154 | C11: =S11*$C$4/100 -> 567.13304 | D11: =S11*$D$4/100 -> 547.74388 | E11: =S11*$E$4/100 -> 479.88181 | F11: =S11*$F$4/100 -> 412.01973 | G11: =S11*$G$4/100 -> 227.82268 | H11: =S11*$H$4/100 -> 213.2808 | I11: =S11*$I$4/100 -> 179.34977 | J11: =S11*$J$4/100 -> 155.11331 | K11: =S11*$K$4/100 -> 121.18227 | L11: =S11*$L$4/100 -> 111.48769 | M11: =S11*$M$4/100 -> 92.098529 | N11: =S11*$N$4/100 -> 87.251238 | O11: =S11*$O$4/100 -> 58.167492 | P11: =S11*$P$4/100 -> 48.47291 | Q11: =S11*$Q$4/100 -> 19.389164 | R11: =S11*$R$4/100 -> 14.541873 | S11: 4226.8377
A12: 2025 | B12: =S12*$B$4/100 -> 1041.4296 | C12: =S12*$C$4/100 -> 662.21341 | D12: =S12*$D$4/100 -> 639.57363 | E12: =S12*$E$4/100 -> 560.33442 | F12: =S12*$F$4/100 -> 481.09521 | G12: =S12*$G$4/100 -> 266.01735 | H12: =S12*$H$4/100 -> 249.03752 | I12: =S12*$I$4/100 -> 209.41791 | J12: =S12*$J$4/100 -> 181.1182 | K12: =S12*$K$4/100 -> 141.49859 | L12: =S12*$L$4/100 -> 130.1787 | M12: =S12*$M$4/100 -> 107.53893 | N12: =S12*$N$4/100 -> 101.87899 | O12: =S12*$O$4/100 -> 67.919324 | P12: =S12*$P$4/100 -> 56.599436 | Q12: =S12*$Q$4/100 -> 22.639775 | R12: =S12*$R$4/100 -> 16.979831 | S12: 4935.4709
A13: 2026 | B13: =S13*$B$4/100 -> 1190.9577 | C13: =S13*$C$4/100 -> 757.29377 | D13: =S13*$D$4/100 -> 731.40338 | E13: =S13*$E$4/100 -> 640.78703 | F13: =S13*$F$4/100 -> 550.17069 | G13: =S13*$G$4/100 -> 304.21203 | H13: =S13*$H$4/100 -> 284.79424 | I13: =S13*$I$4/100 -> 239.48606 | J13: =S13*$J$4/100 -> 207.12308 | K13: =S13*$K$4/100 -> 161.81491 | L13: =S13*$L$4/100 -> 148.86971 | M13: =S13*$M$4/100 -> 122.97933 | N13: =S13*$N$4/100 -> 116.50673 | O13: =S13*$O$4/100 -> 77.671156 | P13: =S13*$P$4/100 -> 64.725963 | Q13: =S13*$Q$4/100 -> 25.890385 | R13: =S13*$R$4/100 -> 19.417789 | S13: 5644.104
A14: 2027 | B14: =S14*$B$4/100 -> 1340.4858 | C14: =S14*$C$4/100 -> 852.37413 | D14: =S14*$D$4/100 -> 823.23313 | E14: =S14*$E$4/100 -> 721.23965 | F14: =S14*$F$4/100 -> 619.24616 | G14: =S14*$G$4/100 -> 342.4067 | H14: =S14*$H$4/100 -> 320.55095 | I14: =S14*$I$4/100 -> 269.55421 | J14: =S14*$J$4/100 -> 233.12797 | K14: =S14*$K$4/100 -> 182.13122 | L14: =S14*$L$4/100 -> 167.56073 | M14: =S14*$M$4/100 -> 138.41973 | N14: =S14*$N$4/100 -> 131.13448 | O14: =S14*$O$4/100 -> 87.422988 | P14: =S14*$P$4/100 -> 72.85249 | Q14: =S14*$Q$4/100 -> 29.140996 | R14: =S14*$R$4/100 -> 21.855747 | S14: 6352.7371
A15: 2028 | B15: =S15*$B$4/100 -> 1490.0139 | C15: =S15*$C$4/100 -> 947.45449 | D15: =S15*$D$4/100 -> 915.06288 | E15: =S15*$E$4/100 -> 801.69226 | F15: =S15*$F$4/100 -> 688.32164 | G15: =S15*$G$4/100 -> 380.60138 | H15: =S15*$H$4/100 -> 356.30767 | I15: =S15*$I$4/100 -> 299.62236 | J15: =S15*$J$4/100 -> 259.13285 | K15: =S15*$K$4/100 -> 202.44754 | L15: =S15*$L$4/100 -> 186.25174 | M15: =S15*$M$4/100 -> 153.86013 | N15: =S15*$N$4/100 -> 145.76223 | O15: =S15*$O$4/100 -> 97.174819 | P15: =S15*$P$4/100 -> 80.979016 | Q15: =S15*$Q$4/100 -> 32.391606 | R15: =S15*$R$4/100 -> 24.293705 | S15: 7061.3702
A16: 2029 | B16: =S16*$B$4/100 -> 1639.542 | C16: =S16*$C$4/100 -> 1042.5349 | D16: =S16*$D$4/100 -> 1006.8926 | E16: =S16*$E$4/100 -> 882.14487 | F16: =S16*$F$4/100 -> 757.39711 | G16: =S16*$G$4/100 -> 418.79605 | H16: =S16*$H$4/100 -> 392.06439 | I16: =S16*$I$4/100 -> 329.69051 | J16: =S16*$J$4/100 -> 285.13774 | K16: =S16*$K$4/100 -> 222.76386 | L16: =S16*$L$4/100 -> 204.94275 | M16: =S16*$M$4/100 -> 169.30053 | N16: =S16*$N$4/100 -> 160.38998 | O16: =S16*$O$4/100 -> 106.92665 | P16: =S16*$P$4/100 -> 89.105543 | Q16: =S16*$Q$4/100 -> 35.642217 | R16: =S16*$R$4/100 -> 26.731663 | S16: 7770.0033
A17: 2030 | B17: =S17*$B$4/100 -> 1789.0701 | C17: =S17*$C$4/100 -> 1137.6152 | D17: =S17*$D$4/100 -> 1098.7224 | E17: =S17*$E$4/100 -> 962.59749 | F17: =S17*$F$4/100 -> 826.47259 | G17: =S17*$G$4/100 -> 456.99073 | H17: =S17*$H$4/100 -> 427.82111 | I17: =S17*$I$4/100 -> 359.75866 | J17: =S17*$J$4/100 -> 311.14262 | K17: =S17*$K$4/100 -> 243.08017 | L17: =S17*$L$4/100 -> 223.63376 | M17: =S17*$M$4/100 -> 184.74093 | N17: =S17*$N$4/100 -> 175.01773 | O17: =S17*$O$4/100 -> 116.67848 | P17: =S17*$P$4/100 -> 97.232069 | Q17: =S17*$Q$4/100 -> 38.892828 | R17: =S17*$R$4/100 -> 29.169621 | S17: 8478.6365
A18: 2031 | B18: =S18*$B$4/100 -> 1938.5982 | C18: =S18*$C$4/100 -> 1232.6956 | D18: =S18*$D$4/100 -> 1190.5521 | E18: =S18*$E$4/100 -> 1043.0501 | F18: =S18*$F$4/100 -> 895.54807 | G18: =S18*$G$4/100 -> 495.1854 | H18: =S18*$H$4/100 -> 463.57782 | I18: =S18*$I$4/100 -> 389.82681 | J18: =S18*$J$4/100 -> 337.14751 | K18: =S18*$K$4/100 -> 263.39649 | L18: =S18*$L$4/100 -> 242.32477 | M18: =S18*$M$4/100 -> 200.18133 | N18: =S18*$N$4/100 -> 189.64547 | O18: =S18*$O$4/100 -> 126.43032 | P18: =S18*$P$4/100 -> 105.3586 | Q18: =S18*$Q$4/100 -> 42.143438 | R18: =S18*$R$4/100 -> 31.607579 | S18: 9187.2696
A19: 2032 | B19: =S19*$B$4/100 -> 2088.1263 | C19: =S19*$C$4/100 -> 1327.7759 | D19: =S19*$D$4/100 -> 1282.3819 | E19: =S19*$E$4/100 -> 1123.5027 | F19: =S19*$F$4/100 -> 964.62354 | G19: =S19*$G$4/100 -> 533.38008 | H19: =S19*$H$4/100 -> 499.33454 | I19: =S19*$I$4/100 -> 419.89495 | J19: =S19*$J$4/100 -> 363.15239 | K19: =S19*$K$4/100 -> 283.71281 | L19: =S19*$L$4/100 -> 261.01578 | M19: =S19*$M$4/100 -> 215.62173 | N19: =S19*$N$4/100 -> 204.27322 | O19: =S19*$O$4/100 -> 136.18215 | P19: =S19*$P$4/100 -> 113.48512 | Q19: =S19*$Q$4/100 -> 45.394049 | R19: =S19*$R$4/100 -> 34.045537 | S19: 9895.9027
A21: PHEV - High
A22: Year | B22: Brunting | C22: Bristol | D22: Vehicle Solutions Leeds | E22: Leeds | F22: Colchester | G22: Wimbledon | H22: Vehicle Solutions Coventry | I22: Manchester | J22: Plymouth | K22: Washington | L22: Northampton | M22: Mansfield | N22: Shotts | O22: ManheimOnline | P22: Birmingham | Q22: Gloucester | R22: Haydock
A23: 2022 | B23: =S23*$B$4/100 -> 632.49151 | C23: =S23*$C$4/100 -> 402.1821 | D23: =S23*$D$4/100 -> 388.43228 | E23: =S23*$E$4/100 -> 340.30793 | F23: =S23*$F$4/100 -> 292.18358 | G23: =S23*$G$4/100 -> 161.56033 | H23: =S23*$H$4/100 -> 151.24797 | I23: =S23*$I$4/100 -> 127.18579 | J23: =S23*$J$4/100 -> 109.99852 | K23: =S23*$K$4/100 -> 85.936346 | L23: =S23*$L$4/100 -> 79.061439 | M23: =S23*$M$4/100 -> 65.311623 | N23: =S23*$N$4/100 -> 61.874169 | O23: =S23*$O$4/100 -> 41.249446 | P23: =S23*$P$4/100 -> 34.374538 | Q23: =S23*$Q$4/100 -> 13.749815 | R23: =S23*$R$4/100 -> 10.312362 | S23: 2997.4598
A24: 2023 | B24: =S24*$B$4/100 -> 867.74558 | C24: =S24*$C$4/100 -> 551.773 | D24: =S24*$D$4/100 -> 532.90897 | E24: =S24*$E$4/100 -> 466.88485 | F24: =S24*$F$4/100 -> 400.86073 | G24: =S24*$G$4/100 -> 221.6524 | H24: =S24*$H$4/100 -> 207.50438 | I24: =S24*$I$4/100 -> 174.49232 | J24: =S24*$J$4/100 -> 150.91227 | K24: =S24*$K$4/100 -> 117.90021 | L24: =S24*$L$4/100 -> 108.4682 | M24: =S24*$M$4/100 -> 89.604163 | N24: =S24*$N$4/100 -> 84.888154 | O24: =S24*$O$4/100 -> 56.592103 | P24: =S24*$P$4/100 -> 47.160086 | Q24: =S24*$Q$4/100 -> 18.864034 | R24: =S24*$R$4/100 -> 14.148026 | S24: 4112.3595
A25: 2024 | B25: =S25*$B$4/100 -> 1130.2499 | C25: =S25*$C$4/100 -> 718.69153 | D25: =S25*$D$4/100 -> 694.12088 | E25: =S25*$E$4/100 -> 608.1236 | F25: =S25*$F$4/100 -> 522.12633 | G25: =S25*$G$4/100 -> 288.70515 | H25: =S25*$H$4/100 -> 270.27716 | I25: =S25*$I$4/100 -> 227.27852 | J25: =S25*$J$4/100 -> 196.56521 | K25: =S25*$K$4/100 -> 153.56657 | L25: =S25*$L$4/100 -> 141.28124 | M25: =S25*$M$4/100 -> 116.71059 | N25: =S25*$N$4/100 -> 110.56793 | O25: =S25*$O$4/100 -> 73.711952 | P25: =S25*$P$4/100 -> 61.426627 | Q25: =S25*$Q$4/100 -> 24.570651 | R25: =S25*$R$4/100 -> 18.427988 | S25: 5356.4018
A26: 2025 | B26: =S26*$B$4/100 -> 1414.549 | C26: =S26*$C$4/100 -> 899.46866 | D26: =S26*$D$4/100 -> 868.7176 | E26: =S26*$E$4/100 -> 761.08887 | F26: =S26*$F$4/100 -> 653.46014 | G26: =S26*$G$4/100 -> 361.32502 | H26: =S26*$H$4/100 -> 338.26172 | I26: =S26*$I$4/100 -> 284.44736 | J26: =S26*$J$4/100 -> 246.00852 | K26: =S26*$K$4/100 -> 192.19416 | L26: =S26*$L$4/100 -> 176.81863 | M26: =S26*$M$4/100 -> 146.06756 | N26: =S26*$N$4/100 -> 138.37979 | O26: =S26*$O$4/100 -> 92.253196 | P26: =S26*$P$4/100 -> 76.877664 | Q26: =S26*$Q$4/100 -> 30.751065 | R26: =S26*$R$4/100 -> 23.063299 | S26: 6703.7323
A27: 2026 | B27: =S27*$B$4/100 -> 1717.5633 | C27: =S27*$C$4/100 -> 1092.1462 | D27: =S27*$D$4/100 -> 1054.8079 | E27: =S27*$E$4/100 -> 924.12372 | F27: =S27*$F$4/100 -> 793.43956 | G27: =S27*$G$4/100 -> 438.7254 | H27: =S27*$H$4/100 -> 410.72165 | I27: =S27*$I$4/100 -> 345.37957 | J27: =S27*$J$4/100 -> 298.70666 | K27: =S27*$K$4/100 -> 233.36458 | L27: =S27*$L$4/100 -> 214.69541 | M27: =S27*$M$4/100 -> 177.35708 | N27: =S27*$N$4/100 -> 168.02249 | O27: =S27*$O$4/100 -> 112.015 | P27: =S27*$P$4/100 -> 93.345831 | Q27: =S27*$Q$4/100 -> 37.338332 | R27: =S27*$R$4/100 -> 28.003749 | S27: 8139.7564
A28: 2027 | B28: =S28*$B$4/100 -> 2037.2404 | C28: =S28*$C$4/100 -> 1295.4191 | D28: =S28*$D$4/100 -> 1251.1313 | E28: =S28*$E$4/100 -> 1096.1239 | F28: =S28*$F$4/100 -> 941.11647 | G28: =S28*$G$4/100 -> 520.38205 | H28: =S28*$H$4/100 -> 487.16617 | I28: =S28*$I$4/100 -> 409.66246 | J28: =S28*$J$4/100 -> 354.30267 | K28: =S28*$K$4/100 -> 276.79896 | L28: =S28*$L$4/100 -> 254.65504 | M28: =S28*$M$4/100 -> 210.36721 | N28: =S28*$N$4/100 -> 199.29525 | O28: =S28*$O$4/100 -> 132.8635 | P28: =S28*$P$4/100 -> 110.71958 | Q28: =S28*$Q$4/100 -> 44.287834 | R28: =S28*$R$4/100 -> 33.215875 | S28: 9654.7477
A29: 2028 | B29: =S29*$B$4/100 -> 2372.085 | C29: =S29*$C$4/100 -> 1508.3366 | D29: =S29*$D$4/100 -> 1456.7696 | E29: =S29*$E$4/100 -> 1276.2849 | F29: =S29*$F$4/100 -> 1095.8001 | G29: =S29*$G$4/100 -> 605.91301 | H29: =S29*$H$4/100 -> 567.23771 | I29: =S29*$I$4/100 -> 476.99535 | J29: =S29*$J$4/100 -> 412.53652 | K29: =S29*$K$4/100 -> 322.29415 | L29: =S29*$L$4/100 -> 296.51062 | M29: =S29*$M$4/100 -> 244.94356 | N29: =S29*$N$4/100 -> 232.05179 | O29: =S29*$O$4/100 -> 154.70119 | P29: =S29*$P$4/100 -> 128.91766 | Q29: =S29*$Q$4/100 -> 51.567065 | R29: =S29*$R$4/100 -> 38.675299 | S29: 11241.62
A30: 2029 | B30: =S30*$B$4/100 -> 2720.9447 | C30: =S30*$C$4/100 -> 1730.1659 | D30: =S30*$D$4/100 -> 1671.0149 | E30: =S30*$E$4/100 -> 1463.9865 | F30: =S30*$F$4/100 -> 1256.9581 | G30: =S30*$G$4/100 -> 695.02392 | H30: =S30*$H$4/100 -> 650.66069 | I30: =S30*$I$4/100 -> 547.14649 | J30: =S30*$J$4/100 -> 473.20777 | K30: =S30*$K$4/100 -> 369.69357 | L30: =S30*$L$4/100 -> 340.11809 | M30: =S30*$M$4/100 -> 280.96711 | N30: =S30*$N$4/100 -> 266.17937 | O30: =S30*$O$4/100 -> 177.45291 | P30: =S30*$P$4/100 -> 147.87743 | Q30: =S30*$Q$4/100 -> 59.150972 | R30: =S30*$R$4/100 -> 44.363229 | S30: 12894.912
A31: 2030 | B31: =S31*$B$4/100 -> 3082.8958 | C31: =S31*$C$4/100 -> 1960.3196 | D31: =S31*$D$4/100 -> 1893.3001 | E31: =S31*$E$4/100 -> 1658.732 | F31: =S31*$F$4/100 -> 1424.1638 | G31: =S31*$G$4/100 -> 787.47882 | H31: =S31*$H$4/100 -> 737.21422 | I31: =S31*$I$4/100 -> 619.93014 | J31: =S31*$J$4/100 -> 536.15579 | K31: =S31*$K$4/100 -> 418.87171 | L31: =S31*$L$4/100 -> 385.36198 | M31: =S31*$M$4/100 -> 318.3425 | N31: =S31*$N$4/100 -> 301.58763 | O31: =S31*$O$4/100 -> 201.05842 | P31: =S31*$P$4/100 -> 167.54869 | Q31: =S31*$Q$4/100 -> 67.019474 | R31: =S31*$R$4/100 -> 50.264606 | S31: 14610.245
A32: 2031 | B32: =S32*$B$4/100 -> 3457.1765 | C32: =S32*$C$4/100 -> 2198.3133 | D32: =S32*$D$4/100 -> 2123.1573 | E32: =S32*$E$4/100 -> 1860.1112 | F32: =S32*$F$4/100 -> 1597.0652 | G32: =S32*$G$4/100 -> 883.08312 | H32: =S32*$H$4/100 -> 826.71611 | I32: =S32*$I$4/100 -> 695.19309 | J32: =S32*$J$4/100 -> 601.24808 | K32: =S32*$K$4/100 -> 469.72506 | L32: =S32*$L$4/100 -> 432.14706 | M32: =S32*$M$4/100 -> 356.99105 | N32: =S32*$N$4/100 -> 338.20204 | O32: =S32*$O$4/100 -> 225.46803 | P32: =S32*$P$4/100 -> 187.89002 | Q32: =S32*$Q$4/100 -> 75.15601 | R32: =S32*$R$4/100 -> 56.367007 | S32: 16384.01
A33: 2032 | B33: =S33*$B$4/100 -> 3843.1441 | C33: =S33*$C$4/100 -> 2443.7384 | D33: =S33*$D$4/100 -> 2360.1917 | E33: =S33*$E$4/100 -> 2067.7786 | F33: =S33*$F$4/100 -> 1775.3655 | G33: =S33*$G$4/100 -> 981.67267 | H33: =S33*$H$4/100 -> 919.01272 | I33: =S33*$I$4/100 -> 772.80615 | J33: =S33*$J$4/100 -> 668.37288 | K33: =S33*$K$4/100 -> 522.16632 | L33: =S33*$L$4/100 -> 480.39301 | M33: =S33*$M$4/100 -> 396.8464 | N33: =S33*$N$4/100 -> 375.95975 | O33: =S33*$O$4/100 -> 250.63983 | P33: =S33*$P$4/100 -> 208.86653 | Q33: =S33*$Q$4/100 -> 83.546611 | R33: =S33*$R$4/100 -> 62.659958 | S33: 18213.161
A35: BEV - Mid
A36: Year | B36: Brunting | C36: Bristol | D36: Vehicle Solutions Leeds | E36: Leeds | F36: Colchester | G36: Wimbledon | H36: Vehicle Solutions Coventry | I36: Manchester | J36: Plymouth | K36: Washington | L36: Northampton | M36: Mansfield | N36: Shotts | O36: ManheimOnline | P36: Birmingham | Q36: Gloucester | R36: Haydock
A37: 2022 | B37: =S37*$B$4/100 -> 913.89212 | C37: =S37*$C$4/100 -> 581.11619 | D37: =S37*$D$4/100 -> 561.24897 | E37: =S37*$E$4/100 -> 491.7137 | F37: =S37*$F$4/100 -> 422.17843 | G37: =S37*$G$4/100 -> 233.43984 | H37: =S37*$H$4/100 -> 218.53942 | I37: =S37*$I$4/100 -> 183.77179 | J37: =S37*$J$4/100 -> 158.93776 | K37: =S37*$K$4/100 -> 124.17013 | L37: =S37*$L$4/100 -> 114.23652 | M37: =S37*$M$4/100 -> 94.369295 | N37: =S37*$N$4/100 -> 89.40249 | O37: =S37*$O$4/100 -> 59.60166 | P37: =S37*$P$4/100 -> 49.66805 | Q37: =S37*$Q$4/100 -> 19.86722 | R37: =S37*$R$4/100 -> 14.900415 | S37: 4331.054
A38: 2023 | B38: =S38*$B$4/100 -> 1385.0399 | C38: =S38*$C$4/100 -> 880.70475 | D38: =S38*$D$4/100 -> 850.59518 | E38: =S38*$E$4/100 -> 745.21171 | F38: =S38*$F$4/100 -> 639.82823 | G38: =S38*$G$4/100 -> 353.78738 | H38: =S38*$H$4/100 -> 331.2052 | I38: =S38*$I$4/100 -> 278.51347 | J38: =S38*$J$4/100 -> 240.87651 | K38: =S38*$K$4/100 -> 188.18477 | L38: =S38*$L$4/100 -> 173.12999 | M38: =S38*$M$4/100 -> 143.02043 | N38: =S38*$N$4/100 -> 135.49304 | O38: =S38*$O$4/100 -> 90.328692 | P38: =S38*$P$4/100 -> 75.27391 | Q38: =S38*$Q$4/100 -> 30.109564 | R38: =S38*$R$4/100 -> 22.582173 | S38: 6563.8849
A39: 2024 | B39: =S39*$B$4/100 -> 1904.2776 | C39: =S39*$C$4/100 -> 1210.8722 | D39: =S39*$D$4/100 -> 1169.4748 | E39: =S39*$E$4/100 -> 1024.5842 | F39: =S39*$F$4/100 -> 879.69347 | G39: =S39*$G$4/100 -> 486.41874 | H39: =S39*$H$4/100 -> 455.37074 | I39: =S39*$I$4/100 -> 382.92539 | J39: =S39*$J$4/100 -> 331.17872 | K39: =S39*$K$4/100 -> 258.73337 | L39: =S39*$L$4/100 -> 238.0347 | M39: =S39*$M$4/100 -> 196.63736 | N39: =S39*$N$4/100 -> 186.28803 | O39: =S39*$O$4/100 -> 124.19202 | P39: =S39*$P$4/100 -> 103.49335 | Q39: =S39*$Q$4/100 -> 41.39734 | R39: =S39*$R$4/100 -> 31.048005 | S39: 9024.6201
A40: 2025 | B40: =S40*$B$4/100 -> 2452.3402 | C40: =S40*$C$4/100 -> 1559.3685 | D40: =S40*$D$4/100 -> 1506.0568 | E40: =S40*$E$4/100 -> 1319.4657 | F40: =S40*$F$4/100 -> 1132.8746 | G40: =S40*$G$4/100 -> 626.413 | H40: =S40*$H$4/100 -> 586.42919 | I40: =S40*$I$4/100 -> 493.13364 | J40: =S40*$J$4/100 -> 426.49395 | K40: =S40*$K$4/100 -> 333.1984 | L40: =S40*$L$4/100 -> 306.54253 | M40: =S40*$M$4/100 -> 253.23079 | N40: =S40*$N$4/100 -> 239.90285 | O40: =S40*$O$4/100 -> 159.93523 | P40: =S40*$P$4/100 -> 133.27936 | Q40: =S40*$Q$4/100 -> 53.311744 | R40: =S40*$R$4/100 -> 39.983808 | S40: 11621.96
A41: 2026 | B41: =S41*$B$4/100 -> 3017.6806 | C41: =S41*$C$4/100 -> 1918.8513 | D41: =S41*$D$4/100 -> 1853.2495 | E41: =S41*$E$4/100 -> 1623.6434 | F41: =S41*$F$4/100 -> 1394.0373 | G41: =S41*$G$4/100 -> 770.8206 | H41: =S41*$H$4/100 -> 721.61928 | I41: =S41*$I$4/100 -> 606.81622 | J41: =S41*$J$4/100 -> 524.81402 | K41: =S41*$K$4/100 -> 410.01096 | L41: =S41*$L$4/100 -> 377.21008 | M41: =S41*$M$4/100 -> 311.60833 | N41: =S41*$N$4/100 -> 295.20789 | O41: =S41*$O$4/100 -> 196.80526 | P41: =S41*$P$4/100 -> 164.00438 | Q41: =S41*$Q$4/100 -> 65.601753 | R41: =S41*$R$4/100 -> 49.201315 | S41: 14301.182
A42: 2027 | B42: =S42*$B$4/100 -> 3593.3774 | C42: =S42*$C$4/100 -> 2284.9193 | D42: =S42*$D$4/100 -> 2206.8024 | E42: =S42*$E$4/100 -> 1933.3933 | F42: =S42*$F$4/100 -> 1659.9841 | G42: =S42*$G$4/100 -> 917.87358 | H42: =S42*$H$4/100 -> 859.28591 | I42: =S42*$I$4/100 -> 722.58133 | J42: =S42*$J$4/100 -> 624.93521 | K42: =S42*$K$4/100 -> 488.23063 | L42: =S42*$L$4/100 -> 449.17218 | M42: =S42*$M$4/100 -> 371.05528 | N42: =S42*$N$4/100 -> 351.52605 | O42: =S42*$O$4/100 -> 234.3507 | P42: =S42*$P$4/100 -> 195.29225 | Q42: =S42*$Q$4/100 -> 78.116901 | R42: =S42*$R$4/100 -> 58.587676 | S42: 17029.484
A43: 2028 | B43: =S43*$B$4/100 -> 4175.2819 | C43: =S43*$C$4/100 -> 2654.9347 | D43: =S43*$D$4/100 -> 2564.1677 | E43: =S43*$E$4/100 -> 2246.4832 | F43: =S43*$F$4/100 -> 1928.7987 | G43: =S43*$G$4/100 -> 1066.5122 | H43: =S43*$H$4/100 -> 998.43698 | I43: =S43*$I$4/100 -> 839.59473 | J43: =S43*$J$4/100 -> 726.13598 | K43: =S43*$K$4/100 -> 567.29374 | L43: =S43*$L$4/100 -> 521.91024 | M43: =S43*$M$4/100 -> 431.14324 | N43: =S43*$N$4/100 -> 408.45149 | O43: =S43*$O$4/100 -> 272.30099 | P43: =S43*$P$4/100 -> 226.91749 | Q43: =S43*$Q$4/100 -> 90.766998 | R43: =S43*$R$4/100 -> 68.075248 | S43: 19787.206
A44: 2029 | B44: =S44*$B$4/100 -> 4760.9073 | C44: =S44*$C$4/100 -> 3027.316 | D44: =S44*$D$4/100 -> 2923.8181 | E44: =S44*$E$4/100 -> 2561.5751 | F44: =S44*$F$4/100 -> 2199.3322 | G44: =S44*$G$4/100 -> 1216.1013 | H44: =S44*$H$4/100 -> 1138.4778 | I44: =S44*$I$4/100 -> 957.35635 | J44: =S44*$J$4/100 -> 827.98387 | K44: =S44*$K$4/100 -> 646.8624 | L44: =S44*$L$4/100 -> 595.11341 | M44: =S44*$M$4/100 -> 491.61543 | N44: =S44*$N$4/100 -> 465.74093 | O44: =S44*$O$4/100 -> 310.49395 | P44: =S44*$P$4/100 -> 258.74496 | Q44: =S44*$Q$4/100 -> 103.49798 | R44: =S44*$R$4/100 -> 77.623488 | S44: 22562.561
...
